<?xml version="1.0" ?>
<!-- =================================================================================== -->
<!-- |    This document was autogenerated by xacro from wagon.xacro                    | -->
<!-- |    EDITING THIS FILE BY HAND IS NOT RECOMMENDED                                 | -->
<!-- =================================================================================== -->
<robot name="wagon">
  <!-- Init colour -->
  <material name="black">
    <color rgba="0.0 0.0 0.0 1.0"/>
  </material>
  <material name="dark">
    <color rgba="0.3 0.3 0.3 1.0"/>
  </material>
  <material name="light_black">
    <color rgba="0.4 0.4 0.4 1.0"/>
  </material>
  <material name="blue">
    <color rgba="0.0 0.0 0.8 1.0"/>
  </material>
  <material name="green">
    <color rgba="0.0 0.8 0.0 1.0"/>
  </material>
  <material name="grey">
    <color rgba="0.5 0.5 0.5 1.0"/>
  </material>
  <material name="orange">
    <color rgba="1.0 0.4235294117647059 0.0392156862745098 1.0"/>
  </material>
  <material name="brown">
    <color rgba="0.8705882352941177 0.8117647058823529 0.7647058823529411 1.0"/>
  </material>
  <material name="red">
    <color rgba="0.8 0.0 0.0 1.0"/>
  </material>
  <material name="white">
    <color rgba="1.0 1.0 1.0 1.0"/>
  </material>
  <material name="acrylic">
    <color rgba="0.9 0.9 1.0 0.6"/>
  </material>
  <link name="base_footprint">
  </link>
  <joint name="base_joint" type="fixed">
    <parent link="base_footprint"/>
    <child link="base_link"/>
    <origin rpy="0 0 0" xyz="0.6948 0 0"/>
  </joint>
  <link name="base_link">
    <visual>
      <origin rpy="0 0 1.57" xyz="0 0 0"/>
      <geometry>
        <mesh filename="package://wagon_description/meshes/bases/Simplified_Front_Centered.stl" scale="0.001 0.001 0.001"/>
      </geometry>
      <material name="white"/>
    </visual>
    <collision>
      <origin rpy="0 0 0" xyz="-0.1873 0 0"/>
      <geometry>
        <box size="1.055 0.620 0.260"/>
      </geometry>
    </collision>
    <inertial>
      <origin rpy="0 1.5707963267948966 0" xyz="-0.142 0 0"/>
      <mass value="135.5"/>
      <inertia ixx="6.189" ixy="0" ixz="-0.009" iyy="17.997" iyz="0" izz="21.229"/>
    </inertial>
  </link>
  <joint name="connection_joint" type="revolute">
    <parent link="base_link"/>
    <child link="connection_link"/>
    <origin rpy="0 0 0" xyz="-0.7866000000000001 0 0"/>
    <axis xyz="1 0 0"/>
    <limit effort="1000.0" lower="-0.350" upper="0.350" velocity="0.5"/>
  </joint>
  <link name="connection_link">
    </link>
  <joint name="hydraulic_joint" type="revolute">
    <axis xyz="0 0 1"/>
    <limit effort="1000.0" lower="-0.70" upper="0.70" velocity="0.5"/>
    <origin rpy="0 0 0" xyz="0.0 0.0 0"/>
    <parent link="connection_link"/>
    <child link="hydraulic_link"/>
  </joint>
  <link name="hydraulic_link">
    </link>
  <joint name="rear_joint" type="fixed">
    <parent link="hydraulic_link"/>
    <child link="rear_link"/>
    <origin rpy="0 0 0" xyz="-0.7866000000000001 0 0"/>
    <axis xyz="1 1 0"/>
  </joint>
  <link name="rear_link">
    <visual>
      <geometry>
        <mesh filename="package://wagon_description/meshes/bases/Simplified_Back_Centered.stl" scale="0.001 0.001 0.001"/>
      </geometry>
      <material name="white"/>
      <origin rpy="0 0 1.5707963267948966" xyz="0 0 0"/>
    </visual>
    <!-- ${-0.8716+hydraulic_offset-(1.180/2)+0.02} -->
    <!-- ${(1.180/2) + 0.8716+hydraulic_offset+0.02-1.180} -->
    <collision>
      <origin rpy="0 0 0" xyz="0.085 0 0"/>
      <geometry>
        <box size="1.02 0.620 0.260"/>
      </geometry>
    </collision>
    <inertial>
      <origin rpy="0 0 0" xyz="0.142 0 0"/>
      <mass value="140.5"/>
      <inertia ixx="6.189" ixy="0" ixz="-0.009" iyy="17.997" iyz="0" izz="21.229"/>
    </inertial>
  </link>
  <joint name="wheel_front_right_joint" type="continuous">
    <parent link="base_link"/>
    <child link="wheel_front_right_link"/>
    <origin rpy="0 0 0" xyz="0 -0.4815 0"/>
    <axis xyz="0 1 0"/>
  </joint>
  <link name="wheel_front_right_link">
    <visual>
      <origin rpy="1.57 0 0" xyz="0 0 0"/>
      <geometry>
        <mesh filename="package://wagon_description/meshes/wheels/Wheel.stl" scale="0.001 0.001 0.001"/>
      </geometry>
      <material name="black"/>
    </visual>
    <collision>
      <origin rpy="1.57 0 0" xyz="0 0 0"/>
      <geometry>
        <cylinder length="0.215" radius="0.292"/>
      </geometry>
    </collision>
    <inertial>
      <origin rpy="1.57 0 0" xyz="0 0 0"/>
      <mass value="40.5"/>
      <inertia ixx="1.05" ixy="1.0783e-10" ixz="-0.023" iyy="1.83" iyz="-0.898e-11" izz="1.05"/>
    </inertial>
  </link>
  <joint name="wheel_front_left_joint" type="continuous">
    <parent link="base_link"/>
    <child link="wheel_front_left_link"/>
    <origin rpy="0 0 0" xyz="0 0.4815 0"/>
    <axis xyz="0 1 0"/>
  </joint>
  <link name="wheel_front_left_link">
    <visual>
      <origin rpy="1.57 0 0" xyz="0 0 0"/>
      <geometry>
        <mesh filename="package://wagon_description/meshes/wheels/Wheel.stl" scale="0.001 0.001 0.001"/>
        <!--
      <origin xyz="0 0 0" rpy="0 0 0"/>
      <geometry>
        <cylinder length="0.07" radius="0.12"/>
        -->
      </geometry>
      <material name="black"/>
    </visual>
    <collision>
      <origin rpy="1.57 0 0" xyz="0 0 0"/>
      <geometry>
        <cylinder length="0.215" radius="0.294"/>
      </geometry>
    </collision>
    <inertial>
      <origin rpy="1.57 0 0" xyz="0 0 0"/>
      <mass value="40.5"/>
      <inertia ixx="1.05" ixy="1.0783e-10" ixz="-0.023" iyy="1.83" iyz="-0.898e-11" izz="1.05"/>
    </inertial>
  </link>
  <joint name="wheel_rear_right_joint" type="continuous">
    <parent link="rear_link"/>
    <child link="wheel_rear_right_link"/>
    <origin rpy="0 0 0" xyz="0 -0.4815 0"/>
    <axis xyz="0 1 0"/>
  </joint>
  <link name="wheel_rear_right_link">
    <visual>
      <origin rpy="1.57 0 0" xyz="0 0 0"/>
      <geometry>
        <mesh filename="package://wagon_description/meshes/wheels/Wheel.stl" scale="0.001 0.001 0.001"/>
        <!--
      <origin xyz="0 0 0" rpy="0 0 0"/>
      <geometry>
        <cylinder length="0.07" radius="0.12"/>
        -->
      </geometry>
      <material name="black"/>
    </visual>
    <collision>
      <origin rpy="1.57 0 0" xyz="0 0 0"/>
      <geometry>
        <cylinder length="0.215" radius="0.294"/>
      </geometry>
    </collision>
    <inertial>
      <origin rpy="0 0 0" xyz="0 0 0"/>
      <mass value="40.5"/>
      <inertia ixx="1.05" ixy="1.0783e-10" ixz="-0.023" iyy="1.83" iyz="-0.898e-11" izz="1.05"/>
    </inertial>
  </link>
  <joint name="wheel_rear_left_joint" type="continuous">
    <parent link="rear_link"/>
    <child link="wheel_rear_left_link"/>
    <origin rpy="0 0 0" xyz="0 0.4815 0"/>
    <axis xyz="0 1 0"/>
  </joint>
  <link name="wheel_rear_left_link">
    <visual>
      <origin rpy="1.57 0 0" xyz="0 0 0"/>
      <geometry>
        <mesh filename="package://wagon_description/meshes/wheels/Wheel.stl" scale="0.001 0.001 0.001"/>
        <!--
      <origin xyz="0 0 0" rpy="0 0 0"/>
      <geometry>
        <cylinder length="0.07" radius="0.12"/>
        -->
      </geometry>
      <material name="black"/>
    </visual>
    <collision>
      <origin rpy="1.57 0 0" xyz="0 0 0"/>
      <geometry>
        <cylinder length="0.215" radius="0.294"/>
      </geometry>
    </collision>
    <inertial>
      <origin rpy="1.57 0 0" xyz="0 0 0"/>
      <mass value="40.5"/>
      <inertia ixx="1.05" ixy="1.0783e-10" ixz="-0.023" iyy="1.83" iyz="-0.898e-11" izz="1.05"/>
    </inertial>
  </link>
  <joint name="imu_joint" type="fixed">
    <parent link="base_link"/>
    <child link="imu_link"/>
    <origin rpy="0 0 0" xyz="-0.032 0 0.068"/>
  </joint>
  <link name="imu_link"/>
  <joint name="scan_joint" type="fixed">
    <parent link="base_link"/>
    <child link="base_scan"/>
    <origin rpy="0 0 0" xyz="0 0 0.272"/>
  </joint>
  <link name="base_scan">
    <visual>
      <origin rpy="1.5707963267948966 0 0" xyz="0 0 -0.036"/>
      <geometry>
        <mesh filename="package://wagon_description/meshes/sensors/ouster_OS1.dae" scale="1 1 1"/>
      </geometry>
      <material name="dark"/>
    </visual>
    <collision>
      <origin rpy="0 0 0" xyz="0 0 0"/>
      <geometry>
        <cylinder length="0.072" radius="0.079"/>
      </geometry>
    </collision>
    <inertial>
      <mass value="0.314"/>
      <origin xyz="0 0 0"/>
      <inertia ixx="0.001" ixy="0.0" ixz="0.0" iyy="0.001" iyz="0.0" izz="0.001"/>
    </inertial>
  </link>
  <joint name="rtk_joint" type="fixed">
    <parent link="base_link"/>
    <child link="rtk_pole"/>
    <origin rpy="0 0 0" xyz="-0.200 0 0.42200000000000004"/>
  </joint>
  <link name="rtk_pole">
    <visual>
      <origin rpy="0 0 0" xyz="0 0 -0.14"/>
      <geometry>
        <!-- <mesh filename="package://wagon_description/meshes/sensors/rtk.dae" scale="1 1 1"/> -->
        <cylinder length="0.28" radius="0.01"/>
      </geometry>
      <material name="dark"/>
    </visual>
    <collision>
      <origin rpy="0 0 0" xyz="0 0 -0.14"/>
      <geometry>
        <cylinder length="0.28" radius="0.01"/>
      </geometry>
    </collision>
    <inertial>
      <mass value="0.314"/>
      <origin xyz="0 0 0"/>
      <inertia ixx="0.001" ixy="0.0" ixz="0.0" iyy="0.001" iyz="0.0" izz="0.001"/>
    </inertial>
  </link>
</robot>
