<?xml version="1.0" ?>
<!-- =================================================================================== -->
<!-- |    This document was autogenerated by xacro from wagon.xacro                    | -->
<!-- |    EDITING THIS FILE BY HAND IS NOT RECOMMENDED                                 | -->
<!-- =================================================================================== -->
<robot name="wagon">
  <!-- Init colour -->
  <material name="black">
    <color rgba="0.0 0.0 0.0 1.0"/>
  </material>
  <material name="dark">
    <color rgba="0.3 0.3 0.3 1.0"/>
  </material>
  <material name="light_black">
    <color rgba="0.4 0.4 0.4 1.0"/>
  </material>
  <material name="blue">
    <color rgba="0.0 0.0 0.8 1.0"/>
  </material>
  <material name="green">
    <color rgba="0.0 0.8 0.0 1.0"/>
  </material>
  <material name="grey">
    <color rgba="0.5 0.5 0.5 1.0"/>
  </material>
  <material name="orange">
    <color rgba="1.0 0.4235294117647059 0.0392156862745098 1.0"/>
  </material>
  <material name="brown">
    <color rgba="0.8705882352941177 0.8117647058823529 0.7647058823529411 1.0"/>
  </material>
  <material name="red">
    <color rgba="0.8 0.0 0.0 1.0"/>
  </material>
  <material name="white">
    <color rgba="1.0 1.0 1.0 1.0"/>
  </material>
  <material name="acrylic">
    <color rgba="0.9 0.9 1.0 0.6"/>
  </material>
  <link name="base_footprint"/>
  <joint name="base_joint" type="fixed">
    <parent link="base_footprint"/>
    <child link="base_link"/>
    <origin rpy="0 0 0" xyz="0.6948 0 0"/>
  </joint>
  <link name="base_link">
    <visual>
      <origin rpy="0 0 1.57" xyz="0 0 0"/>
      <geometry>
        <mesh filename="$(find wagon_description)/meshes/bases/Simplified_Front_Centered.stl" scale="0.001 0.001 0.001"/>
      </geometry>
      <material name="dark"/>
    </visual>
    <collision>
      <origin rpy="0 0 0" xyz="-0.142 0 0"/>
      <geometry>
        <box size="0.42 0.25 0.12"/>
      </geometry>
    </collision>
    <inertial>
      <origin rpy="0 0 0" xyz="-0.142 0 0"/>
      <mass value="7.5"/>
      <inertia ixx="4.806e-2" ixy="0.0" ixz="0.0" iyy="1.193e-1" iyz="0.0" izz="1.493e-1"/>
    </inertial>
  </link>
  <joint name="hydrolic_joint" type="revolute">
    <axis xyz="0 0 1"/>
    <limit effort="1000.0" lower="-0.550" upper="0.550" velocity="0.5"/>
    <origin rpy="0 0 0" xyz="-0.7797999999999999 0.0 0"/>
    <parent link="base_link"/>
    <child link="hydrolic_link"/>
  </joint>
  <link name="hydrolic_link">
    </link>
  <joint name="rear_joint" type="fixed">
    <parent link="hydrolic_link"/>
    <child link="rear_link"/>
    <origin rpy="0 0 0" xyz="-0.7866000000000001 0 0"/>
  </joint>
  <link name="rear_link">
    <visual>
      <origin rpy="0 0 1.57" xyz="0 0 0"/>
      <geometry>
        <mesh filename="$(find wagon_description)/meshes/bases/Simplified_Back_Centered.stl" scale="0.001 0.001 0.001"/>
      </geometry>
      <material name="dark"/>
    </visual>
    <collision>
      <origin rpy="0 0 0" xyz="-0.142 0 0"/>
      <geometry>
        <box size="0.42 0.25 0.12"/>
      </geometry>
    </collision>
    <inertial>
      <origin rpy="0 0 0" xyz="-0.142 0 0"/>
      <mass value="7.5"/>
      <inertia ixx="4.806e-2" ixy="0.0" ixz="0.0" iyy="1.193e-1" iyz="0.0" izz="1.493e-1"/>
    </inertial>
  </link>
  <joint name="wheel_front_right_joint" type="continuous">
    <parent link="base_link"/>
    <child link="wheel_front_right_link"/>
    <origin rpy="0 0 0" xyz="0 -0.4815 0"/>
    <axis xyz="0 1 0"/>
  </joint>
  <link name="wheel_front_right_link">
    <visual>
      <origin rpy="1.57 0 0" xyz="0 0 0"/>
      <geometry>
        <mesh filename="$(find wagon_description)/meshes/wheels/Wheel.stl" scale="0.001 0.001 0.001"/>
        <!--
      <origin xyz="0 0 0" rpy="0 0 0"/>
      <geometry>
        <cylinder length="0.07" radius="0.12"/>
        -->
      </geometry>
      <material name="black"/>
    </visual>
    <collision>
      <origin rpy="0 0 0" xyz="0 0 0"/>
      <geometry>
        <cylinder length="0.215" radius="0.294"/>
      </geometry>
    </collision>
    <inertial>
      <origin rpy="0 0 0" xyz="0 0 0"/>
      <mass value="1.525"/>
      <inertia ixx="6.723e-3" ixy="0.0" ixz="0.0" iyy="6.723e-3" iyz="0.0" izz="1.220e-2"/>
    </inertial>
  </link>
  <joint name="wheel_front_left_joint" type="continuous">
    <parent link="base_link"/>
    <child link="wheel_front_left_link"/>
    <origin rpy="0 0 0" xyz="0 0.4815 0"/>
    <axis xyz="0 1 0"/>
  </joint>
  <link name="wheel_front_left_link">
    <visual>
      <origin rpy="1.57 0 0" xyz="0 0 0"/>
      <geometry>
        <mesh filename="$(find wagon_description)/meshes/wheels/Wheel.stl" scale="0.001 0.001 0.001"/>
        <!--
      <origin xyz="0 0 0" rpy="0 0 0"/>
      <geometry>
        <cylinder length="0.07" radius="0.12"/>
        -->
      </geometry>
      <material name="black"/>
    </visual>
    <collision>
      <origin rpy="0 0 0" xyz="0 0 0"/>
      <geometry>
        <cylinder length="0.215" radius="0.294"/>
      </geometry>
    </collision>
    <inertial>
      <origin rpy="0 0 0" xyz="0 0 0"/>
      <mass value="1.525"/>
      <inertia ixx="6.723e-3" ixy="0.0" ixz="0.0" iyy="6.723e-3" iyz="0.0" izz="1.220e-2"/>
    </inertial>
  </link>
  <joint name="wheel_rear_right_joint" type="continuous">
    <parent link="rear_link"/>
    <child link="wheel_rear_right_link"/>
    <origin rpy="0 0 0" xyz="0 -0.4815 0"/>
    <axis xyz="0 1 0"/>
  </joint>
  <link name="wheel_rear_right_link">
    <visual>
      <origin rpy="1.57 0 0" xyz="0 0 0"/>
      <geometry>
        <mesh filename="$(find wagon_description)/meshes/wheels/Wheel.stl" scale="0.001 0.001 0.001"/>
        <!--
      <origin xyz="0 0 0" rpy="0 0 0"/>
      <geometry>
        <cylinder length="0.07" radius="0.12"/>
        -->
      </geometry>
      <material name="black"/>
    </visual>
    <collision>
      <origin rpy="0 0 0" xyz="0 0 0"/>
      <geometry>
        <cylinder length="0.215" radius="0.294"/>
      </geometry>
    </collision>
    <inertial>
      <origin rpy="0 0 0" xyz="0 0 0"/>
      <mass value="1.525"/>
      <inertia ixx="6.723e-3" ixy="0.0" ixz="0.0" iyy="6.723e-3" iyz="0.0" izz="1.220e-2"/>
    </inertial>
  </link>
  <joint name="wheel_rear_left_joint" type="continuous">
    <parent link="rear_link"/>
    <child link="wheel_rear_left_link"/>
    <origin rpy="0 0 0" xyz="0 0.4815 0"/>
    <axis xyz="0 1 0"/>
  </joint>
  <link name="wheel_rear_left_link">
    <visual>
      <origin rpy="1.57 0 0" xyz="0 0 0"/>
      <geometry>
        <mesh filename="$(find wagon_description)/meshes/wheels/Wheel.stl" scale="0.001 0.001 0.001"/>
        <!--
      <origin xyz="0 0 0" rpy="0 0 0"/>
      <geometry>
        <cylinder length="0.07" radius="0.12"/>
        -->
      </geometry>
      <material name="black"/>
    </visual>
    <collision>
      <origin rpy="0 0 0" xyz="0 0 0"/>
      <geometry>
        <cylinder length="0.215" radius="0.294"/>
      </geometry>
    </collision>
    <inertial>
      <origin rpy="0 0 0" xyz="0 0 0"/>
      <mass value="1.525"/>
      <inertia ixx="6.723e-3" ixy="0.0" ixz="0.0" iyy="6.723e-3" iyz="0.0" izz="1.220e-2"/>
    </inertial>
  </link>
</robot>
