<sdf version='1.9'>
  <model name='wagon'>
    <link name='base_footprint'>
      <inertial>
        <pose>0.5528 0 0 0 0 0</pose>
        <mass>135.5</mass>
        <inertia>
          <ixx>21.228999999999999</ixx>
          <ixy>0</ixy>
          <ixz>0.0090000000000009205</ixz>
          <iyy>17.996999999999989</iyy>
          <iyz>0</iyz>
          <izz>6.188999999999993</izz>
        </inertia>
      </inertial>
      <collision name='base_footprint_fixed_joint_lump__base_link_collision'>
        <pose>0.5075 0 0 0 0 0</pose>
        <geometry>
          <box>
            <size>1.055 0.62 0.26</size>
          </box>
        </geometry>
      </collision>
      <visual name='base_footprint_fixed_joint_lump__base_link_visual'>
        <pose>0.6948 0 0 0 0 1.57</pose>
        <geometry>
          <mesh>
            <scale>0.001 0.001 0.001</scale>
            <uri>/home/daniel/master_ws/install/wagon_description/share/wagon_description/meshes/bases/Simplified_Front_Centered.stl</uri>
          </mesh>
        </geometry>
        <material>
          <diffuse>1 1 1 1</diffuse>
          <ambient>1 1 1 1</ambient>
        </material>
      </visual>
    </link>
    <joint name='hydrolic_joint' type='revolute'>
      <pose relative_to='base_footprint'>-0.08499999999999996 0 0 0 0 0</pose>
      <parent>base_footprint</parent>
      <child>hydrolic_link</child>
      <axis>
        <xyz>0 0 1</xyz>
        <limit>
          <lower>-0.55000000000000004</lower>
          <upper>0.55000000000000004</upper>
          <effort>1000</effort>
          <velocity>0.5</velocity>
        </limit>
        <dynamics>
          <spring_reference>0</spring_reference>
          <spring_stiffness>0</spring_stiffness>
        </dynamics>
      </axis>
    </joint>
    <link name='hydrolic_link'>
      <pose relative_to='hydrolic_joint'>0 0 0 0 0 0</pose>
      <inertial>
        <pose>-0.6446000000000001 0 0 0 0 0</pose>
        <mass>140.5</mass>
        <inertia>
          <ixx>6.1890000000000001</ixx>
          <ixy>0</ixy>
          <ixz>-0.0089999999999999993</ixz>
          <iyy>17.996999999999989</iyy>
          <iyz>0</iyz>
          <izz>21.228999999999989</izz>
        </inertia>
      </inertial>
      <collision name='hydrolic_link_fixed_joint_lump__rear_link_collision'>
        <pose>-0.6966000000000001 0 0 0 0 0</pose>
        <geometry>
          <box>
            <size>1.02 0.62 0.26</size>
          </box>
        </geometry>
      </collision>
      <visual name='hydrolic_link_fixed_joint_lump__rear_link_visual'>
        <pose>-0.7866000000000001 0 0 0 0 1.57</pose>
        <geometry>
          <mesh>
            <scale>0.001 0.001 0.001</scale>
            <uri>/home/daniel/master_ws/install/wagon_description/share/wagon_description/meshes/bases/Simplified_Back_Centered.stl</uri>
          </mesh>
        </geometry>
        <material>
          <diffuse>1 1 1 1</diffuse>
          <ambient>1 1 1 1</ambient>
        </material>
      </visual>
    </link>
    <joint name='wheel_rear_left_joint' type='revolute'>
      <pose relative_to='hydrolic_link'>-0.7866000000000001 0.4815 0 0 0 0</pose>
      <parent>hydrolic_link</parent>
      <child>wheel_rear_left_link</child>
      <axis>
        <xyz>0 1 0</xyz>
        <limit>
          <lower>-10000000000000000</lower>
          <upper>10000000000000000</upper>
        </limit>
        <dynamics>
          <spring_reference>0</spring_reference>
          <spring_stiffness>0</spring_stiffness>
        </dynamics>
      </axis>
    </joint>
    <link name='wheel_rear_left_link'>
      <pose relative_to='wheel_rear_left_joint'>0 0 0 0 0 0</pose>
      <inertial>
        <pose>0 0 0 1.57 0 0</pose>
        <mass>40.5</mass>
        <inertia>
          <ixx>1.05</ixx>
          <ixy>1.0783e-10</ixy>
          <ixz>-0.023</ixz>
          <iyy>1.8300000000000001</iyy>
          <iyz>-8.9799999999999993e-12</iyz>
          <izz>1.05</izz>
        </inertia>
      </inertial>
      <collision name='wheel_rear_left_link_collision'>
        <pose>0 0 0 1.57 0 0</pose>
        <geometry>
          <cylinder>
            <length>0.215</length>
            <radius>0.29399999999999998</radius>
          </cylinder>
        </geometry>
      </collision>
      <visual name='wheel_rear_left_link_visual'>
        <pose>0 0 0 1.57 0 0</pose>
        <geometry>
          <mesh>
            <scale>0.001 0.001 0.001</scale>
            <uri>/home/daniel/master_ws/install/wagon_description/share/wagon_description/meshes/wheels/Wheel.stl</uri>
          </mesh>
        </geometry>
        <material>
          <diffuse>0 0 0 1</diffuse>
          <ambient>0 0 0 1</ambient>
        </material>
      </visual>
    </link>
    <joint name='wheel_rear_right_joint' type='revolute'>
      <pose relative_to='hydrolic_link'>-0.7866000000000001 -0.4815 0 0 0 0</pose>
      <parent>hydrolic_link</parent>
      <child>wheel_rear_right_link</child>
      <axis>
        <xyz>0 1 0</xyz>
        <limit>
          <lower>-10000000000000000</lower>
          <upper>10000000000000000</upper>
        </limit>
        <dynamics>
          <spring_reference>0</spring_reference>
          <spring_stiffness>0</spring_stiffness>
        </dynamics>
      </axis>
    </joint>
    <link name='wheel_rear_right_link'>
      <pose relative_to='wheel_rear_right_joint'>0 0 0 0 0 0</pose>
      <inertial>
        <pose>0 0 0 0 0 0</pose>
        <mass>40.5</mass>
        <inertia>
          <ixx>1.05</ixx>
          <ixy>1.0783e-10</ixy>
          <ixz>-0.023</ixz>
          <iyy>1.8300000000000001</iyy>
          <iyz>-8.9799999999999993e-12</iyz>
          <izz>1.05</izz>
        </inertia>
      </inertial>
      <collision name='wheel_rear_right_link_collision'>
        <pose>0 0 0 1.57 0 0</pose>
        <geometry>
          <cylinder>
            <length>0.215</length>
            <radius>0.29399999999999998</radius>
          </cylinder>
        </geometry>
      </collision>
      <visual name='wheel_rear_right_link_visual'>
        <pose>0 0 0 1.57 0 0</pose>
        <geometry>
          <mesh>
            <scale>0.001 0.001 0.001</scale>
            <uri>/home/daniel/master_ws/install/wagon_description/share/wagon_description/meshes/wheels/Wheel.stl</uri>
          </mesh>
        </geometry>
        <material>
          <diffuse>0 0 0 1</diffuse>
          <ambient>0 0 0 1</ambient>
        </material>
      </visual>
    </link>
    <joint name='wheel_front_left_joint' type='revolute'>
      <pose relative_to='base_footprint'>0.6948 0.4815 0 0 0 0</pose>
      <parent>base_footprint</parent>
      <child>wheel_front_left_link</child>
      <axis>
        <xyz>0 1 0</xyz>
        <limit>
          <lower>-10000000000000000</lower>
          <upper>10000000000000000</upper>
        </limit>
        <dynamics>
          <spring_reference>0</spring_reference>
          <spring_stiffness>0</spring_stiffness>
        </dynamics>
      </axis>
    </joint>
    <link name='wheel_front_left_link'>
      <pose relative_to='wheel_front_left_joint'>0 0 0 0 0 0</pose>
      <inertial>
        <pose>0 0 0 1.57 0 0</pose>
        <mass>40.5</mass>
        <inertia>
          <ixx>1.05</ixx>
          <ixy>1.0783e-10</ixy>
          <ixz>-0.023</ixz>
          <iyy>1.8300000000000001</iyy>
          <iyz>-8.9799999999999993e-12</iyz>
          <izz>1.05</izz>
        </inertia>
      </inertial>
      <collision name='wheel_front_left_link_collision'>
        <pose>0 0 0 1.57 0 0</pose>
        <geometry>
          <cylinder>
            <length>0.215</length>
            <radius>0.29399999999999998</radius>
          </cylinder>
        </geometry>
      </collision>
      <visual name='wheel_front_left_link_visual'>
        <pose>0 0 0 1.57 0 0</pose>
        <geometry>
          <mesh>
            <scale>0.001 0.001 0.001</scale>
            <uri>/home/daniel/master_ws/install/wagon_description/share/wagon_description/meshes/wheels/Wheel.stl</uri>
          </mesh>
        </geometry>
        <material>
          <diffuse>0 0 0 1</diffuse>
          <ambient>0 0 0 1</ambient>
        </material>
      </visual>
    </link>
    <joint name='wheel_front_right_joint' type='revolute'>
      <pose relative_to='base_footprint'>0.6948 -0.4815 0 0 0 0</pose>
      <parent>base_footprint</parent>
      <child>wheel_front_right_link</child>
      <axis>
        <xyz>0 1 0</xyz>
        <limit>
          <lower>-10000000000000000</lower>
          <upper>10000000000000000</upper>
        </limit>
        <dynamics>
          <spring_reference>0</spring_reference>
          <spring_stiffness>0</spring_stiffness>
        </dynamics>
      </axis>
    </joint>
    <link name='wheel_front_right_link'>
      <pose relative_to='wheel_front_right_joint'>0 0 0 0 0 0</pose>
      <inertial>
        <pose>0 0 0 1.57 0 0</pose>
        <mass>40.5</mass>
        <inertia>
          <ixx>1.05</ixx>
          <ixy>1.0783e-10</ixy>
          <ixz>-0.023</ixz>
          <iyy>1.8300000000000001</iyy>
          <iyz>-8.9799999999999993e-12</iyz>
          <izz>1.05</izz>
        </inertia>
      </inertial>
      <collision name='wheel_front_right_link_collision'>
        <pose>0 0 0 1.57 0 0</pose>
        <geometry>
          <cylinder>
            <length>0.215</length>
            <radius>0.29199999999999998</radius>
          </cylinder>
        </geometry>
      </collision>
      <visual name='wheel_front_right_link_visual'>
        <pose>0 0 0 1.57 0 0</pose>
        <geometry>
          <mesh>
            <scale>0.001 0.001 0.001</scale>
            <uri>/home/daniel/master_ws/install/wagon_description/share/wagon_description/meshes/wheels/Wheel.stl</uri>
          </mesh>
        </geometry>
        <material>
          <diffuse>0 0 0 1</diffuse>
          <ambient>0 0 0 1</ambient>
        </material>
      </visual>
    </link>
    <plugin
        filename="ignition-gazebo-joint-state-publisher-system"
        name="ignition::gazebo::systems::JointStatePublisher">
    </plugin>

    <plugin
        filename="ignition-gazebo-pose-publisher-system"
        name="ignition::gazebo::systems::PosePublisher">
        <publish_link_pose>true</publish_link_pose>

        <use_pose_vector_msg>true</use_pose_vector_msg>
    </plugin>
    <!-- <plugin
        filename="ignition-gazebo-joint-controller-system"
        name="ignition::gazebo::systems::JointController">
        <joint_name>hydrolic_joint</joint_name>
        <topic>/hydrolic_joint/cmd_vel</topic>
        <initial_velocity>2</initial_velocity>
    </plugin> -->

    <plugin
        filename="ignition-gazebo-joint-position-controller-system"
        name="ignition::gazebo::systems::JointPositionController">
        <joint_name>hydrolic_joint</joint_name>
        <joint_index>0</joint_index>
        <p_gain>500</p_gain>
        <i_gain>0.1</i_gain>
        <d_gain>0.1</d_gain>
        <i_max>1</i_max>
        <i_min>-1</i_min>
        <cmd_max>1000</cmd_max>
        <cmd_offset>0</cmd_offset> 

    </plugin>

  </model>
</sdf>
